[META]
version=2.0
spawnOnBlockType=2
spawnSunlight=True
spawnDarkness=False
spawnWater=False
spawnLava=False
underFill=False
randomRotation=False
dig=True
tree=True
branch=False
needsFoundation=True
rarity=120
collisionPercentage=2
spawnElevationMin=0
spawnElevationMax=95
spawnInBiome=Tallforest
[DATA]
0,0,0:17.3
0,0,1:17.3
0,0,2:17.3
0,0,3:17.3
0,0,4:17.3
0,0,5:17.3
0,0,6:17.3
-1,-2,7:18
0,-2,7:18
1,-2,7:18
-2,-1,7:18
-1,-1,7:18
0,-1,7:18
1,-1,7:18
2,-1,7:18
-2,0,7:18
-1,0,7:18
0,0,7:17.3
1,0,7:18
2,0,7:18
-2,1,7:18
-1,1,7:18
0,1,7:18
1,1,7:18
2,1,7:18
-1,2,7:18
0,2,7:18
1,2,7:18
-1,-1,8:18
0,-1,8:18
1,-1,8:18
-1,0,8:18
0,0,8:17.3
1,0,8:18
-1,1,8:18
0,1,8:18
1,1,8:18
-1,-2,9:18
0,-2,9:18
1,-2,9:18
-2,-1,9:18
-1,-1,9:18
0,-1,9:18
1,-1,9:18
2,-1,9:18
-2,0,9:18
-1,0,9:18
0,0,9:17.3
1,0,9:18
2,0,9:18
-2,1,9:18
-1,1,9:18
0,1,9:18
1,1,9:18
2,1,9:18
-1,2,9:18
0,2,9:18
1,2,9:18
-1,-1,10:18
0,-1,10:18
1,-1,10:18
-1,0,10:18
0,0,10:17.3
1,0,10:18
-1,1,10:18
0,1,10:18
1,1,10:18
-1,-2,11:18
0,-2,11:18
1,-2,11:18
-2,-1,11:18
-1,-1,11:18
0,-1,11:18
1,-1,11:18
2,-1,11:18
-2,0,11:18
-1,0,11:18
0,0,11:17.3
1,0,11:18
2,0,11:18
-2,1,11:18
-1,1,11:18
0,1,11:18
1,1,11:18
2,1,11:18
-1,2,11:18
0,2,11:18
1,2,11:18
-1,-1,12:18
0,-1,12:18
1,-1,12:18
-1,0,12:18
0,0,12:17.3
1,0,12:18
-1,1,12:18
0,1,12:18
1,1,12:18
-1,-2,13:18
0,-2,13:18
1,-2,13:18
-2,-1,13:18
-1,-1,13:18
0,-1,13:18
1,-1,13:18
2,-1,13:18
-2,0,13:18
-1,0,13:18
0,0,13:17.3
1,0,13:18
2,0,13:18
-2,1,13:18
-1,1,13:18
0,1,13:18
1,1,13:18
2,1,13:18
-1,2,13:18
0,2,13:18
1,2,13:18
-1,-1,14:18
0,-1,14:18
1,-1,14:18
-1,0,14:18
0,0,14:17.3
1,0,14:18
-1,1,14:18
0,1,14:18
1,1,14:18
-1,-2,15:18
0,-2,15:18
1,-2,15:18
-2,-1,15:18
-1,-1,15:18
0,-1,15:18
1,-1,15:18
2,-1,15:18
-2,0,15:18
-1,0,15:18
0,0,15:17.3
1,0,15:18
2,0,15:18
-2,1,15:18
-1,1,15:18
0,1,15:18
1,1,15:18
2,1,15:18
-1,2,15:18
0,2,15:18
1,2,15:18
-1,-1,16:18
0,-1,16:18
1,-1,16:18
-1,0,16:18
0,0,16:17.3
1,0,16:18
-1,1,16:18
0,1,16:18
1,1,16:18
-1,-2,17:18
0,-2,17:18
1,-2,17:18
-2,-1,17:18
-1,-1,17:18
0,-1,17:18
1,-1,17:18
2,-1,17:18
-2,0,17:18
-1,0,17:18
0,0,17:17.3
1,0,17:18
2,0,17:18
-2,1,17:18
-1,1,17:18
0,1,17:18
1,1,17:18
2,1,17:18
-1,2,17:18
0,2,17:18
1,2,17:18
-1,-1,18:18
0,-1,18:18
1,-1,18:18
-1,0,18:18
0,0,18:17.3
1,0,18:18
-1,1,18:18
0,1,18:18
1,1,18:18
-1,-2,19:18
0,-2,19:18
1,-2,19:18
-2,-1,19:18
-1,-1,19:18
0,-1,19:18
1,-1,19:18
2,-1,19:18
-2,0,19:18
-1,0,19:18
0,0,19:17.3
1,0,19:18
2,0,19:18
-2,1,19:18
-1,1,19:18
0,1,19:18
1,1,19:18
2,1,19:18
-1,2,19:18
0,2,19:18
1,2,19:18
-1,-1,20:18
0,-1,20:18
1,-1,20:18
-1,0,20:18
0,0,20:17.3
1,0,20:18
-1,1,20:18
0,1,20:18
1,1,20:18
0,-1,21:18
-1,0,21:18
0,0,21:18
1,0,21:18
0,1,21:18
0,0,22:18
