[META]
version=2.0
spawnOnBlockType=2
spawnSunlight=True
spawnDarkness=False
spawnWater=False
spawnLava=False
underFill=False
randomRotation=True
dig=True
tree=True
branch=False
needsFoundation=True
rarity=900
collisionPercentage=2
spawnElevationMin=80
spawnElevationMax=95
spawnInBiome=Fractures
[DATA]
0,0,0:17.0
0,0,1:17.0
0,0,2:17.0
-1,0,2:18.0
0,-1,2:18.0
0,1,2:18.0
1,0,2:18.0
2,0,2:18.0
1,1,2:18.0
1,-1,2:18.0
2,-1,2:18.0
2,1,2:18.0
3,0,2:18.0
0,0,3:17.0
1,0,3:17.0
2,0,3:17.0
2,1,3:18.0
1,1,3:18.0
0,1,3:18.0
-1,0,3:18.0
0,-1,3:18.0
1,-1,3:18.0
2,-1,3:18.0
3,0,3:18.0
0,2,3:18.0
1,2,3:18.0
2,2,3:18.0
3,1,3:18.0
4,0,3:18.0
3,-1,3:18.0
2,-2,3:18.0
1,-2,3:18.0
0,-2,3:18.0
-1,-1,3:18.0
-1,1,3:18.0
4,-1,3:106.2
4,1,3:106.2
5,0,3:106.2
3,2,3:106.2
3,-2,3:106.2
0,0,4:17.0
3,0,4:17.0
3,-1,4:18.0
2,-1,4:18.0
1,-1,4:18.0
0,-1,4:18.0
-1,-1,4:18.0
0,-2,4:18.0
1,-2,4:18.0
2,-2,4:18.0
2,0,4:18.0
1,0,4:18.0
4,0,4:18.0
3,1,4:18.0
2,1,4:18.0
1,1,4:18.0
0,1,4:18.0
-1,1,4:18.0
-1,0,4:18.0
0,2,4:18.0
1,2,4:18.0
2,2,4:18.0
3,2,4:18.0
-1,2,4:18.0
4,1,4:18.0
4,-1,4:18.0
3,-2,4:18.0
-1,-2,4:18.0
5,-1,4:106.2
5,0,4:106.2
5,1,4:106.2
4,2,4:106.2
4,-2,4:106.2
0,0,5:17.0
3,1,5:18.0
4,0,5:18.0
3,-1,5:18.0
2,-1,5:18.0
2,-2,5:18.0
1,-2,5:18.0
1,-1,5:18.0
0,-2,5:18.0
0,-1,5:18.0
-1,-1,5:18.0
-1,0,5:18.0
-1,1,5:18.0
0,1,5:18.0
0,2,5:18.0
1,2,5:18.0
2,2,5:18.0
2,1,5:18.0
1,1,5:18.0
1,0,5:18.0
2,0,5:18.0
3,0,5:18.0
4,-1,5:106.2
4,1,5:106.2
3,2,5:106.2
3,-2,5:106.2
0,-1,6:18.0
1,-1,6:18.0
2,-1,6:18.0
2,0,6:18.0
2,1,6:18.0
1,1,6:18.0
0,1,6:18.0
0,0,6:18.0
1,0,6:18.0
