[META]
version=2.0
spawnOnBlockType=2
spawnSunlight=True
spawnDarkness=False
spawnWater=False
spawnLava=False
underFill=False
randomRotation=True
dig=False
tree=False
branch=False
needsFoundation=True
rarity=2
collisionPercentage=100
spawnElevationMin=0
spawnElevationMax=80
spawnInBiome=Extreme Hills,Forest,ForestAutumn
[DATA]
0,1,0:17.0
-1,1,0:18.0
0,2,0:18.0
-1,2,0:18.0
-1,0,0:18.0
0,0,0:18.0
0,-1,0:18.0
-1,-1,0:18.0
-2,1,0:18.0
1,1,0:18.0
1,0,0:18.0
1,2,0:18.0
0,3,0:18.0
-1,3,0:18.0
2,1,0:18.0
1,3,0:18.0
2,2,0:18.0
0,-2,0:18.0
-1,-2,0:18.0
1,-1,0:18.0
-2,0,0:18.0
-2,2,0:18.0
2,-1,0:18.0
2,0,0:18.0
-1,4,0:18.0
-3,1,0:18.0
3,1,0:18.0
0,4,0:18.0
0,1,1:17
0,0,1:18.0
-1,3,1:18.0
3,1,1:18.0
0,1,2:17
0,1,3:17
0,1,4:17
0,1,5:17
0,1,6:17
0,1,7:17
0,1,8:17
1,-1,9:17
1,0,9:17
-1,1,9:17
0,1,9:17
-2,-7,10:18
-2,-6,10:18
-1,-6,10:18
-3,-5,10:18
0,-5,10:18
0,-3,10:17
0,-2,10:17
3,-2,10:17
4,-2,10:18
2,-1,10:17
3,-1,10:17
5,-1,10:18
6,-1,10:18
-6,0,10:18
-5,0,10:18
-4,0,10:17
-3,0,10:17
4,0,10:17
5,0,10:18
6,0,10:18
7,0,10:18
-7,1,10:18
-6,1,10:18
-5,1,10:18
-2,1,10:17
4,1,10:18
5,1,10:18
-6,2,10:18
1,2,10:17
1,3,10:17
2,3,10:17
0,4,10:17
-2,6,10:18
-1,6,10:18
0,6,10:18
1,6,10:18
2,6,10:18
-2,7,10:18
1,7,10:18
2,7,10:18
-3,-6,11:18
-1,-6,11:18
0,-6,11:18
1,-6,11:18
-4,-5,11:18
-3,-5,11:17
-2,-5,11:18
-1,-5,11:18
0,-5,11:17
1,-5,11:18
2,-5,11:18
-3,-4,11:18
-2,-4,11:17
-1,-4,11:17
0,-4,11:18
1,-4,11:18
2,-4,11:18
3,-4,11:18
4,-4,11:18
-3,-3,11:18
2,-3,11:18
3,-3,11:18
4,-3,11:17
5,-3,11:18
-4,-2,11:18
4,-2,11:18
5,-2,11:18
-5,-1,11:18
-4,-1,11:17
-1,-1,11:17
4,-1,11:18
5,-1,11:18
-5,0,11:18
5,0,11:18
6,0,11:18
-6,1,11:18
-5,1,11:17
2,1,11:17
5,1,11:17
6,1,11:18
-6,2,11:18
-5,2,11:18
5,2,11:18
6,2,11:18
-5,3,11:18
-4,3,11:18
-3,3,11:17
-2,3,11:17
-1,3,11:17
4,3,11:18
5,3,11:18
-4,4,11:18
-3,4,11:18
3,4,11:17
4,4,11:17
5,4,11:18
-3,5,11:18
-2,5,11:18
-1,5,11:17
1,5,11:17
3,5,11:18
4,5,11:18
5,5,11:18
-3,6,11:18
-2,6,11:17
-1,6,11:18
0,6,11:18
1,6,11:17
2,6,11:18
3,6,11:18
-3,7,11:18
-2,7,11:18
-1,7,11:18
0,7,11:18
1,7,11:18
-3,-5,12:18
0,-5,12:18
-2,-4,12:18
-1,-4,12:18
0,-4,12:18
-2,-3,12:18
-1,-3,12:18
0,-3,12:18
1,-3,12:18
3,-3,12:18
4,-3,12:18
-3,-2,12:18
-2,-2,12:18
1,-2,12:18
2,-2,12:18
3,-2,12:18
4,-2,12:18
-4,-1,12:18
-3,-1,12:18
-2,-1,12:18
3,-1,12:18
-4,0,12:18
-3,0,12:18
0,0,12:17
3,0,12:17
4,0,12:18
-5,1,12:18
-4,1,12:18
-3,1,12:18
3,1,12:18
4,1,12:18
5,1,12:18
-4,2,12:18
-3,2,12:18
1,2,12:17
2,2,12:18
3,2,12:18
4,2,12:18
-3,3,12:18
-2,3,12:18
-1,3,12:18
1,3,12:18
3,3,12:18
4,3,12:18
-2,4,12:18
-1,4,12:18
0,4,12:18
1,4,12:18
2,4,12:18
3,4,12:18
4,4,12:18
-1,5,12:18
0,5,12:18
1,5,12:18
2,5,12:18
-2,6,12:18
1,6,12:18
-1,-2,13:18
0,-2,13:18
-1,-1,13:18
0,-1,13:18
1,-1,13:18
2,-1,13:18
-2,0,13:18
-1,0,13:18
0,0,13:18
1,0,13:18
2,0,13:18
3,0,13:18
-2,1,13:18
-1,1,13:18
0,1,13:17
1,1,13:18
2,1,13:18
-2,2,13:18
-1,2,13:18
0,2,13:18
1,2,13:18
2,2,13:18
-2,3,13:18
-1,3,13:18
0,3,13:18
1,3,13:18
2,3,13:18
0,0,14:18
1,0,14:18
0,1,14:18
1,1,14:18
-1,2,14:18
0,2,14:18
