[META]
version=2.0
spawnOnBlockType=3,2
spawnSunlight=True
spawnDarkness=True
spawnWater=False
spawnLava=False
underFill=True
randomRotation=True
dig=True
tree=True
branch=False
needsFoundation=True
rarity=5
collisionPercentage=10
spawnElevationMin=0
spawnElevationMax=100
spawnInBiome=Swampland
[DATA]
-1,0,0:17.0
0,0,0:17.0
0,1,0:17.0
-1,1,0:17.0
-2,-1,0:17.0
-2,0,0:17.0
-2,1,0:17.0
-2,2,0:17.0
-1,2,0:17.0
0,2,0:17.0
1,2,0:17.0
1,1,0:17.0
1,0,0:17.0
1,-1,0:17.0
0,-1,0:17.0
-1,-1,0:17.0
-3,1,0:17.0
-1,3,0:17.0
0,3,0:17.0
0,-2,0:17.0
2,0,0:17.0
-1,0,1:17.0
0,0,1:17.0
0,1,1:17.0
-1,1,1:17.0
-1,3,1:17.0
-1,2,1:17.0
1,1,1:17.0
1,0,1:17.0
0,2,1:17.0
1,-1,1:17.0
2,0,1:17.0
0,-1,1:17.0
0,-2,1:17.0
-1,-1,1:17.0
-2,-1,1:17.0
-2,0,1:17.0
-2,1,1:17.0
-3,1,1:17.0
-2,2,1:17.0
-1,0,2:17.0
0,0,2:17.0
0,1,2:17.0
-1,1,2:17.0
-2,0,2:17.0
-2,1,2:17.0
-1,-1,2:17.0
0,-1,2:17.0
1,0,2:17.0
1,1,2:17.0
-1,2,2:17.0
0,2,2:17.0
-1,0,3:17.0
0,0,3:17.0
0,1,3:17.0
-1,1,3:17.0
-2,1,3:17.0
-1,2,3:17.0
1,1,3:17.0
1,0,3:17.0
0,-1,3:17.0
-1,0,4:17.0
0,0,4:17.0
0,1,4:17.0
-1,1,4:17.0
-2,1,4:17.0
1,0,4:17.0
-1,0,5:17.0
0,0,5:17.0
0,1,5:17.0
-1,1,5:17.0
-2,1,5:17.0
1,0,5:17.0
2,5,5:18.0
-6,6,5:18.0
-6,7,5:18.0
-7,6,5:18.0
-6,5,5:18.0
-5,6,5:18.0
1,5,5:18.0
2,4,5:18.0
3,5,5:18.0
2,6,5:18.0
1,6,5:106.1
-7,5,5:106.1
-1,0,6:17.0
0,0,6:17.0
0,1,6:17.0
-1,1,6:17.0
-2,1,6:17.0
2,5,6:17.0
-6,6,6:17.0
1,5,6:18.0
2,4,6:18.0
3,5,6:18.0
2,6,6:18.0
-6,5,6:18.0
-7,6,6:18.0
-7,7,6:18.0
-5,6,6:18.0
-5,7,6:18.0
-6,8,6:18.0
-6,-5,6:18.0
-9,1,6:18.0
-8,1,6:18.0
-8,2,6:18.0
1,4,6:18.0
3,4,6:18.0
2,3,6:18.0
3,6,6:18.0
1,6,6:18.0
0,5,6:18.0
-5,5,6:18.0
-7,5,6:18.0
-6,4,6:18.0
-5,8,6:18.0
-8,6,6:18.0
-4,7,6:18.0
4,5,6:18.0
4,0,6:18.0
-1,-7,6:18.0
-6,7,6:18.0
-7,-5,6:18.0
-6,-6,6:18.0
-5,-5,6:18.0
-6,-4,6:18.0
-2,-7,6:18.0
-1,-8,6:18.0
0,-7,6:18.0
-1,-6,6:18.0
3,0,6:18.0
4,-1,6:18.0
5,0,6:18.0
4,1,6:18.0
2,7,6:18.0
3,7,6:18.0
4,6,6:18.0
4,4,6:18.0
5,5,6:18.0
2,8,6:18.0
1,7,6:18.0
0,6,6:18.0
5,-1,6:106.1
3,1,6:106.1
1,-7,6:106.1
-3,-7,6:106.1
-7,-6,6:106.1
-5,-4,6:106.1
-7,4,6:106.1
-4,6,6:106.1
-1,0,7:17.0
0,0,7:17.0
0,1,7:17.0
-1,1,7:17.0
-6,-5,7:17.0
1,5,7:17.0
-5,7,7:17.0
-8,2,7:17.0
-8,1,7:17.0
-9,1,7:17.0
-6,6,7:17.0
-5,6,7:18.0
-7,7,7:18.0
-6,8,7:18.0
-5,8,7:18.0
-4,7,7:18.0
0,5,7:18.0
1,4,7:18.0
2,5,7:18.0
1,6,7:18.0
-7,-5,7:18.0
-6,-6,7:18.0
-5,-5,7:18.0
-6,-4,7:18.0
-10,1,7:18.0
-9,0,7:18.0
-8,0,7:18.0
-7,1,7:18.0
-9,2,7:18.0
-8,3,7:18.0
-7,2,7:18.0
-7,0,7:18.0
-9,3,7:18.0
-7,3,7:18.0
-6,2,7:18.0
-6,1,7:18.0
-8,4,7:18.0
-7,-4,7:18.0
-5,-4,7:18.0
-5,-6,7:18.0
-4,-4,7:18.0
-4,-5,7:18.0
-5,-3,7:18.0
-7,-6,7:18.0
-6,-7,7:18.0
-8,-5,7:18.0
4,0,7:17.0
4,-1,7:18.0
5,0,7:18.0
3,-1,7:18.0
3,0,7:18.0
4,1,7:18.0
3,1,7:18.0
2,0,7:18.0
2,-1,7:18.0
-1,-7,7:17.0
-2,-7,7:18.0
-2,-8,7:18.0
-1,-8,7:18.0
-1,-9,7:18.0
0,-8,7:18.0
0,-7,7:18.0
-3,-7,7:18.0
-3,-6,7:18.0
1,-7,7:18.0
1,-6,7:18.0
2,-6,7:18.0
-1,-6,7:18.0
0,-6,7:18.0
0,-5,7:18.0
-1,-5,7:18.0
-2,-6,7:18.0
-2,-5,7:18.0
5,-1,7:18.0
3,-2,7:18.0
4,-2,7:18.0
2,-2,7:18.0
2,1,7:18.0
3,2,7:18.0
4,2,7:18.0
6,0,7:18.0
5,1,7:18.0
0,4,7:18.0
1,3,7:18.0
2,4,7:18.0
0,6,7:18.0
0,7,7:18.0
1,7,7:18.0
2,6,7:18.0
-1,6,7:18.0
-1,5,7:18.0
-7,6,7:18.0
-6,5,7:18.0
-5,5,7:18.0
-4,6,7:18.0
-7,4,7:106.1
-1,4,7:106.1
2,3,7:106.1
5,-2,7:106.1
5,2,7:106.1
1,-1,7:106.1
-5,-7,7:106.1
-7,-3,7:106.1
-4,-3,7:106.1
0,-4,7:106.1
-3,-5,7:106.1
2,-7,7:106.1
-3,7,7:106.1
-1,0,8:17.0
0,0,8:17.0
0,1,8:17.0
-1,1,8:17.0
4,-3,8:17.0
-6,-4,8:17.0
1,4,8:17.0
-4,7,8:17.0
-5,7,8:17.0
-8,3,8:17.0
-8,2,8:17.0
-1,-1,8:17.0
-7,-4,8:18.0
-6,-5,8:18.0
-5,-4,8:18.0
-6,-3,8:18.0
-9,2,8:18.0
-9,3,8:18.0
-8,1,8:18.0
-8,4,8:18.0
-7,2,8:18.0
-7,3,8:18.0
-6,7,8:18.0
-5,6,8:18.0
-4,6,8:18.0
-3,7,8:18.0
-4,8,8:18.0
-5,8,8:18.0
0,4,8:18.0
1,3,8:18.0
2,4,8:18.0
1,6,8:18.0
3,-3,8:18.0
4,-4,8:18.0
5,-3,8:18.0
4,-2,8:18.0
-7,-3,8:18.0
-8,-4,8:18.0
3,-4,8:18.0
2,-3,8:18.0
5,-4,8:18.0
4,-5,8:18.0
2,-2,8:18.0
3,-2,8:18.0
5,-2,8:18.0
6,-3,8:18.0
1,5,8:18.0
-9,1,8:18.0
0,5,8:18.0
-1,4,8:18.0
0,3,8:18.0
2,5,8:18.0
2,3,8:18.0
1,2,8:18.0
4,0,8:17.0
3,0,8:18.0
2,0,8:18.0
3,1,8:18.0
-1,-6,8:17.0
-1,-7,8:18.0
0,-6,8:18.0
-2,-6,8:18.0
-2,-5,8:18.0
-3,-6,8:18.0
-2,-7,8:18.0
-1,-8,8:18.0
0,-7,8:18.0
1,-6,8:18.0
0,-5,8:18.0
0,-4,8:106.1
-4,5,8:106.1
-6,-2,8:106.1
3,4,8:106.1
5,-5,8:106.1
6,-2,8:106.1
-3,-5,8:106.1
-1,0,9:17.0
0,0,9:17.0
0,1,9:17.0
-1,1,9:17.0
-4,7,9:17.0
2,5,9:17.0
3,-3,9:17.0
-6,-3,9:17.0
0,4,9:17.0
-1,-2,9:17.0
-1,-3,9:17.0
-7,3,9:17.0
-8,3,9:17.0
-7,-3,9:18.0
-6,-4,9:18.0
-5,-3,9:18.0
-6,-2,9:18.0
-7,-2,9:18.0
-8,2,9:18.0
-7,2,9:18.0
-9,3,9:18.0
-8,4,9:18.0
-7,4,9:18.0
-6,3,9:18.0
-5,7,9:18.0
-4,6,9:18.0
-3,7,9:18.0
-4,8,9:18.0
-1,4,9:18.0
0,3,9:18.0
1,4,9:18.0
0,5,9:18.0
1,5,9:18.0
2,4,9:18.0
3,5,9:18.0
2,6,9:18.0
2,-3,9:18.0
3,-4,9:18.0
4,-3,9:18.0
3,-2,9:18.0
2,-4,9:18.0
3,-5,9:18.0
1,-3,9:18.0
2,-2,9:18.0
1,3,9:18.0
-1,3,9:18.0
-1,5,9:18.0
-2,4,9:18.0
2,7,9:18.0
4,5,9:18.0
3,6,9:18.0
3,4,9:18.0
3,0,9:17.0
1,0,9:17.0
4,0,9:18.0
3,-1,9:18.0
3,1,9:18.0
2,0,9:18.0
2,-1,9:18.0
2,1,9:18.0
-1,-5,9:17.0
-2,-5,9:18.0
-1,-6,9:18.0
-2,-6,9:18.0
-1,-7,9:18.0
0,-6,9:18.0
0,-5,9:18.0
1,-1,9:106.1
0,-4,9:106.1
-3,-5,9:106.1
-4,-3,9:106.1
-2,7,9:106.1
-5,3,9:106.1
-1,2,9:106.1
-4,5,9:106.1
-1,0,10:17.0
0,0,10:17.0
0,1,10:17.0
-1,1,10:17.0
-7,3,10:17.0
-5,-3,10:17.0
2,-3,10:17.0
-4,-3,10:17.0
-4,6,10:17.0
-4,5,10:17.0
-1,4,10:17.0
-1,3,10:17.0
-1,-4,10:17.0
-1,-3,10:17.0
-2,1,10:17.0
1,-3,10:18.0
2,-4,10:18.0
3,-3,10:18.0
2,-2,10:18.0
-1,5,10:18.0
0,4,10:18.0
-2,4,10:18.0
-8,3,10:18.0
-7,2,10:18.0
-6,3,10:18.0
-7,4,10:18.0
-6,-3,10:18.0
-5,-4,10:18.0
-4,-4,10:18.0
-5,-2,10:18.0
-3,-3,10:18.0
-3,-7,10:18.0
3,-5,10:18.0
-5,6,10:18.0
-3,6,10:18.0
-4,7,10:18.0
2,5,10:18.0
2,0,10:17.0
3,0,10:18.0
-2,-4,10:18.0
-2,-5,10:18.0
-1,-5,10:18.0
-1,-6,10:18.0
0,-5,10:18.0
1,6,10:17.0
0,7,10:18.0
1,7,10:18.0
-3,-5,10:106.1
0,-4,10:106.1
1,-1,10:106.1
-5,3,10:106.1
-2,7,10:106.1
0,0,11:17.0
0,1,11:17.0
-1,1,11:17.0
-1,0,11:17.0
3,-5,11:17.0
-1,2,11:17.0
-3,-2,11:17.0
-4,-2,11:17.0
-3,-1,11:17.0
-7,2,11:17.0
-6,2,11:17.0
-4,4,11:17.0
-4,3,11:17.0
2,-2,11:17.0
2,-1,11:17.0
-3,-7,11:17.0
-3,-5,11:17.0
-2,-5,11:17.0
-2,-4,11:17.0
-3,2,11:17.0
-3,1,11:17.0
-1,5,11:17.0
1,2,11:17.0
1,1,11:17.0
-4,-7,11:18.0
-3,-8,11:18.0
-2,-7,11:18.0
-3,-6,11:18.0
-4,-5,11:18.0
2,-5,11:18.0
3,-6,11:18.0
3,-4,11:18.0
4,-5,11:18.0
-3,5,11:18.0
-7,3,11:18.0
-5,-3,11:18.0
-4,-3,11:18.0
4,3,11:18.0
-7,1,11:18.0
-8,2,11:18.0
-5,-1,11:18.0
-2,-8,11:18.0
-1,-7,11:18.0
-3,-9,11:18.0
-4,-8,11:18.0
-5,-8,11:18.0
-5,-7,11:18.0
-5,-6,11:18.0
-4,-6,11:18.0
-6,-6,11:18.0
-2,-6,11:18.0
-1,-5,11:18.0
-1,-4,11:18.0
-3,-4,11:18.0
-3,-3,11:18.0
-4,-1,11:18.0
-4,1,11:18.0
-4,2,11:18.0
-6,1,11:18.0
-6,3,11:18.0
-5,4,11:18.0
-3,4,11:18.0
-4,5,11:18.0
-4,6,11:18.0
-1,4,11:18.0
-1,3,11:18.0
0,3,11:18.0
-2,4,11:18.0
-1,-3,11:18.0
0,-5,11:18.0
1,-4,11:18.0
2,-4,11:18.0
2,-3,11:18.0
3,-3,11:18.0
3,-2,11:18.0
3,-1,11:18.0
0,5,11:17.0
1,5,11:17.0
1,7,11:17.0
0,7,11:17.0
2,7,11:18.0
1,8,11:18.0
0,8,11:18.0
-1,7,11:18.0
0,-4,11:106.1
5,-5,11:106.1
-5,3,11:106.1
-2,7,11:106.1
-6,-3,11:106.1
-6,-7,11:106.1
-1,-2,11:106.1
1,-1,11:106.1
-3,-6,12:17.0
1,-1,12:17.0
1,0,12:17.0
-2,-1,12:17.0
-2,0,12:17.0
-5,2,12:17.0
-4,2,12:17.0
-1,0,12:17.0
-1,1,12:17.0
0,1,12:17.0
0,0,12:17.0
-3,5,12:17.0
3,2,12:17.0
2,2,12:17.0
-2,5,12:17.0
2,-5,12:17.0
1,-5,12:17.0
4,3,12:17.0
3,-5,12:18.0
-3,6,12:18.0
-4,5,12:18.0
-3,4,12:18.0
-3,-7,12:18.0
-4,-6,12:18.0
-2,-6,12:18.0
-3,-5,12:18.0
2,-6,12:18.0
2,-4,12:18.0
1,-6,12:18.0
3,3,12:18.0
4,2,12:18.0
4,4,12:18.0
5,3,12:18.0
3,1,12:18.0
-5,-1,12:17.0
-6,-1,12:18.0
-5,-2,12:18.0
-5,0,12:18.0
-2,-5,12:18.0
-2,-4,12:18.0
1,-2,12:18.0
1,-3,12:18.0
2,-2,12:18.0
2,-1,12:18.0
1,2,12:18.0
1,1,12:18.0
2,1,12:18.0
-1,5,12:18.0
-1,4,12:18.0
-2,6,12:18.0
-1,6,12:18.0
-2,4,12:18.0
-7,2,12:18.0
-6,2,12:18.0
-4,4,12:18.0
-4,3,12:18.0
-3,3,12:18.0
-4,-2,12:18.0
-3,2,12:18.0
0,8,12:17.0
-1,8,12:18.0
0,9,12:18.0
1,8,12:18.0
0,10,12:18.0
-1,9,12:18.0
1,9,12:18.0
-2,8,12:18.0
2,8,12:18.0
-1,7,12:18.0
0,7,12:18.0
1,7,12:18.0
0,5,12:18.0
1,5,12:18.0
2,-7,12:106.1
5,2,12:106.1
-2,7,12:106.1
-5,3,12:106.1
-3,6,13:17.0
4,2,13:17.0
-1,0,13:17.0
-1,1,13:17.0
0,1,13:17.0
0,0,13:17.0
0,-4,13:17.0
1,-4,13:17.0
0,-3,13:17.0
-4,6,13:18.0
-2,6,13:18.0
-3,7,13:18.0
-3,5,13:18.0
-3,-6,13:18.0
1,-5,13:18.0
0,-5,13:18.0
-1,-4,13:18.0
2,-3,13:18.0
1,-3,13:18.0
2,-5,13:18.0
2,-4,13:18.0
4,3,13:18.0
3,2,13:17.0
-4,0,13:17.0
-4,-1,13:17.0
-5,-1,13:18.0
-1,-3,13:18.0
0,-2,13:18.0
1,-2,13:18.0
-3,-1,13:18.0
-3,-2,13:18.0
-4,-2,13:18.0
-4,1,13:18.0
-3,0,13:18.0
5,2,13:18.0
4,1,13:18.0
3,1,13:18.0
2,3,13:18.0
3,3,13:18.0
2,2,13:18.0
2,1,13:18.0
3,0,13:18.0
2,0,13:18.0
3,-2,13:18.0
2,-2,13:18.0
-5,0,13:18.0
-6,-2,13:18.0
-6,-1,13:18.0
-5,-2,13:18.0
-6,0,13:18.0
-5,1,13:18.0
-5,2,13:18.0
-4,2,13:18.0
0,8,13:18.0
0,9,13:18.0
-1,8,13:18.0
0,7,13:18.0
1,8,13:18.0
-6,-3,13:106.1
-2,7,13:106.1
-5,3,13:106.1
-1,-2,13:106.1
0,-3,14:17.0
0,-2,14:17.0
0,-1,14:17.0
-3,6,14:18.0
1,-4,14:18.0
-2,1,14:17.0
-3,1,14:17.0
-4,1,14:17.0
-4,-2,14:18.0
-4,-1,14:18.0
3,2,14:18.0
2,2,14:18.0
1,2,14:18.0
1,1,14:18.0
-1,-2,14:18.0
-1,-1,14:18.0
-1,-3,14:18.0
-3,0,14:18.0
-3,-1,14:18.0
-2,-1,14:18.0
-2,0,14:18.0
-2,-2,14:18.0
-3,2,14:18.0
-2,2,14:18.0
-2,3,14:18.0
-1,2,14:18.0
0,2,14:18.0
0,1,14:18.0
0,0,14:18.0
1,0,14:18.0
1,-1,14:18.0
1,-2,14:18.0
2,-1,14:18.0
2,0,14:18.0
-1,0,14:18.0
-1,1,14:18.0
-1,3,14:18.0
0,3,14:18.0
2,1,14:18.0
-3,3,14:18.0
-4,6,14:18.0
-3,7,14:18.0
-2,8,14:18.0
-2,7,14:18.0
-2,6,14:18.0
-3,5,14:18.0
-2,5,14:18.0
0,-4,14:18.0
-4,0,14:18.0
3,0,14:106.1
-1,4,14:106.1
-2,-3,14:106.1
-1,6,14:106.1
-4,7,14:106.1
-4,1,15:18.0
-3,1,15:18.0
-2,1,15:18.0
0,-3,15:18.0
0,-2,15:18.0
0,-1,15:18.0
-1,-1,15:18.0
-1,-2,15:18.0
-2,-1,15:18.0
-2,0,15:18.0
-3,0,15:18.0
-1,0,15:18.0
-3,-1,15:18.0
-2,-2,15:18.0
-1,-3,15:18.0
1,-3,15:18.0
1,-2,15:18.0
1,-1,15:18.0
2,-1,15:18.0
2,-2,15:18.0
2,0,15:18.0
1,0,15:18.0
3,0,15:18.0
2,1,15:18.0
3,-1,15:18.0
3,1,15:18.0
4,1,15:18.0
1,1,15:18.0
0,1,15:18.0
-1,1,15:18.0
-1,2,15:18.0
0,2,15:18.0
-2,2,15:18.0
-3,2,15:18.0
-3,3,15:18.0
-2,3,15:18.0
-1,3,15:18.0
0,3,15:18.0
2,2,15:18.0
2,3,15:18.0
1,3,15:18.0
1,2,15:18.0
0,4,15:18.0
-1,4,15:18.0
1,4,15:18.0
3,2,15:18.0
2,-3,15:106.1
1,5,15:106.1
-4,3,15:106.1
-5,1,15:106.1
-2,-3,15:106.1
4,0,15:106.1
-2,4,15:106.1
3,3,15:106.1
-1,0,-1:17.0
0,0,-1:17.0
0,1,-1:17.0
-1,1,-1:17.0
-2,2,-1:17.0
-2,1,-1:17.0
-2,0,-1:17.0
-2,-1,-1:17.0
-1,-1,-1:17.0
0,-1,-1:17.0
1,-1,-1:17.0
1,0,-1:17.0
1,1,-1:17.0
-1,2,-1:17.0
-1,3,-1:17.0
0,2,-1:17.0
-3,1,-1:17.0
0,-2,-1:17.0
2,0,-1:17.0
0,3,-1:17.0
1,2,-1:17.0
-2,1,-2:17.0
-2,0,-2:17.0
-2,2,-2:17.0
0,-2,-2:17.0
0,-1,-2:17.0
1,-1,-2:17.0
1,2,-2:17.0
1,1,-2:17.0
0,2,-2:17.0
0,3,-2:17.0
-3,1,-2:17.0
-1,0,-2:17.0
-1,1,-2:17.0
-1,2,-2:17.0
0,0,-2:17.0
0,1,-2:17.0
-1,-1,-2:17.0
0,3,-3:17.0
-3,1,-3:17.0
-4,1,-3:17.0
0,-2,-3:17.0
0,-1,-3:17.0
0,1,-3:17.0
0,0,-3:17.0
0,2,-3:17.0
-1,0,-3:17.0
-1,1,-3:17.0
-1,2,-3:17.0
-2,1,-3:17.0
-2,0,-3:17.0
-2,2,-3:17.0
-1,-1,-3:17.0
1,0,-3:17.0
-2,-1,-3:17.0
2,0,-3:17.0
-2,0,16:18.0
-1,0,16:18.0
-1,-1,16:18.0
0,-1,16:18.0
1,-1,16:18.0
1,0,16:18.0
1,1,16:18.0
1,2,16:18.0
0,2,16:18.0
0,1,16:18.0
0,0,16:18.0
-1,1,16:18.0
-1,2,16:18.0
-2,2,16:18.0
-2,1,16:18.0
-3,1,16:18.0
0,-2,16:18.0
2,1,16:18.0
1,3,16:18.0
0,3,16:18.0
2,0,16:18.0
-1,1,17:18.0
-1,0,17:18.0
0,0,17:18.0
0,-1,17:18.0
-2,1,17:18.0
0,1,17:18.0
1,1,17:18.0
0,2,17:18.0
0,3,17:106.1
0,-2,17:106.1
-3,1,17:106.1
2,1,17:106.1
