[META]
version=2.0
spawnOnBlockType=2
spawnSunlight=True
spawnDarkness=False
spawnWater=False
spawnLava=False
underFill=False
randomRotation=False
dig=True
tree=True
branch=False
needsFoundation=True
rarity=50
collisionPercentage=2
spawnElevationMin=0
spawnElevationMax=256
spawnInBiome=Tallforest
[DATA]
0,0,0:17.1
0,0,1:17.1
0,-1,1:18.1
-1,-1,1:18.1
-1,0,1:18.1
-1,1,1:18.1
0,1,1:18.1
1,1,1:18.1
1,0,1:18.1
1,-1,1:18.1
0,-2,1:18.1
2,0,1:18.1
-2,0,1:18.1
0,2,1:18.1
0,0,2:17.1
0,1,2:18.1
1,0,2:18.1
0,-1,2:18.1
-1,0,2:18.1
0,0,3:17.1
1,-1,3:18.1
0,-1,3:18.1
-1,-1,3:18.1
-1,0,3:18.1
-1,1,3:18.1
0,1,3:18.1
1,1,3:18.1
1,0,3:18.1
0,-1,4:18.1
0,0,4:18.1
0,1,4:18.1
1,0,4:18.1
-1,0,4:18.1
0,0,5:18.1
0,0,6:18.1
