[META]
version=2.0
spawnOnBlockType=2
spawnSunlight=True
spawnDarkness=False
spawnWater=False
spawnLava=False
underFill=False
randomRotation=False
dig=False
tree=True
branch=False
needsFoundation=True
rarity=600
collisionPercentage=99
spawnElevationMin=0
spawnElevationMax=65
spawnInBiome=Fractures
[DATA]
0,0,0:17.0
0,0,1:17.0
0,0,2:17.0
0,0,3:17.0
1,0,3:18.0
0,-1,3:18.0
1,-1,3:18.0
-1,-1,3:18.0
-1,0,3:18.0
-1,1,3:18.0
0,1,3:18.0
1,1,3:18.0
0,2,3:18.0
0,-2,3:18.0
2,0,3:18.0
-2,0,3:18.0
0,0,4:17.0
0,-2,4:18.0
0,-1,4:18.0
1,-1,4:18.0
1,0,4:18.0
1,1,4:18.0
2,0,4:18.0
0,1,4:18.0
0,2,4:18.0
-1,1,4:18.0
-1,0,4:18.0
-1,-1,4:18.0
-2,0,4:18.0
0,-3,4:18.0
-1,-2,4:18.0
-2,-1,4:18.0
-3,0,4:18.0
-2,1,4:18.0
-1,2,4:18.0
0,3,4:18.0
1,2,4:18.0
2,1,4:18.0
3,0,4:18.0
2,-1,4:18.0
1,-2,4:18.0
0,0,5:17.0
0,-3,5:18.0
0,-2,5:17.0
0,-1,5:17.0
1,-2,5:18.0
1,-1,5:18.0
1,0,5:17.0
1,1,5:18.0
1,2,5:18.0
0,1,5:17.0
0,2,5:17.0
0,3,5:18.0
-1,2,5:18.0
-1,1,5:18.0
-1,0,5:17.0
-1,-1,5:18.0
-1,-2,5:18.0
-2,-1,5:18.0
-2,0,5:17.0
-2,1,5:18.0
-3,0,5:18.0
2,-1,5:18.0
2,0,5:17.0
2,1,5:18.0
3,0,5:18.0
1,-3,5:18.0
2,-2,5:18.0
3,-1,5:18.0
3,1,5:18.0
2,2,5:18.0
1,3,5:18.0
-1,3,5:18.0
-2,2,5:18.0
-3,1,5:18.0
-3,-1,5:18.0
-2,-2,5:18.0
-1,-3,5:18.0
0,0,6:17.0
3,0,6:18.0
2,0,6:18.0
2,-1,6:18.0
2,1,6:18.0
1,2,6:18.0
0,3,6:18.0
-1,2,6:18.0
-2,1,6:18.0
-3,0,6:18.0
-2,-1,6:18.0
-1,-2,6:18.0
0,-3,6:18.0
1,-2,6:18.0
0,-2,6:18.0
0,-1,6:18.0
1,-1,6:18.0
1,0,6:18.0
1,1,6:18.0
0,1,6:18.0
0,2,6:18.0
-1,1,6:18.0
-1,0,6:18.0
-1,-1,6:18.0
-2,0,6:18.0
0,0,7:17.0
2,0,7:18.0
1,-1,7:18.0
0,-2,7:18.0
-1,-1,7:18.0
-2,0,7:18.0
-1,0,7:18.0
-1,1,7:18.0
0,1,7:18.0
1,1,7:18.0
1,0,7:18.0
0,-1,7:18.0
0,2,7:18.0
0,0,8:18.0
1,0,8:18.0
0,1,8:18.0
-1,0,8:18.0
0,-1,8:18.0
