[META]
version=2.0
spawnOnBlockType=2
spawnSunlight=True
spawnDarkness=False
spawnWater=False
spawnLava=False
underFill=False
randomRotation=True
dig=True
tree=True
branch=False
needsFoundation=True
rarity=1
collisionPercentage=100
spawnElevationMin=0
spawnElevationMax=128
spawnInBiome=Custom
[DATA]
2,-12,0:106.1
1,-11,0:106.8
1,-9,0:106.8
1,-8,0:2
2,-8,0:2
3,-8,0:2
0,-7,0:2
1,-7,0:2
2,-7,0:17.1
3,-7,0:2
4,-7,0:2
5,-7,0:2
-1,-6,0:2
0,-6,0:2
1,-6,0:2
2,-6,0:3
3,-6,0:2
4,-6,0:2
5,-6,0:2
6,-6,0:2
7,-6,0:106.1
-1,-5,0:17.1
0,-5,0:17.1
1,-5,0:3
2,-5,0:3
3,-5,0:2
4,-5,0:3
5,-5,0:2
6,-5,0:2
7,-5,0:2
8,-5,0:106.11
-6,-4,0:106.8
-1,-4,0:17.1
0,-4,0:17.1
1,-4,0:3
2,-4,0:3
3,-4,0:3
4,-4,0:3
5,-4,0:2
6,-4,0:2
7,-4,0:2
8,-4,0:2
9,-4,0:106.6
-2,-3,0:2
-1,-3,0:2
0,-3,0:3
1,-3,0:3
2,-3,0:3
3,-3,0:3
4,-3,0:3
5,-3,0:3
6,-3,0:2
7,-3,0:2
8,-3,0:2
-7,-2,0:106.1
-6,-2,0:106.1
-3,-2,0:2
-2,-2,0:2
-1,-2,0:3
0,-2,0:3
1,-2,0:3
2,-2,0:3
3,-2,0:3
4,-2,0:3
5,-2,0:3
6,-2,0:3
7,-2,0:3
8,-2,0:2
-8,-1,0:106.8
-3,-1,0:2
-2,-1,0:2
-1,-1,0:3
0,-1,0:3
1,-1,0:3
2,-1,0:3
3,-1,0:3
4,-1,0:3
5,-1,0:3
6,-1,0:3
7,-1,0:2
8,-1,0:2
-2,0,0:17.1
-1,0,0:17.1
0,0,0:3
1,0,0:3
2,0,0:3
3,0,0:3
4,0,0:3
5,0,0:3
6,0,0:3
7,0,0:2
-2,1,0:2
-1,1,0:2
0,1,0:3
1,1,0:3
2,1,0:3
3,1,0:3
4,1,0:3
5,1,0:3
6,1,0:2
7,1,0:2
-2,2,0:2
-1,2,0:3
0,2,0:3
1,2,0:3
2,2,0:3
3,2,0:3
4,2,0:3
5,2,0:2
6,2,0:2
-2,3,0:2
-1,3,0:3
0,3,0:3
1,3,0:3
2,3,0:3
3,3,0:3
4,3,0:2
5,3,0:2
-1,4,0:2
0,4,0:3
1,4,0:3
2,4,0:3
3,4,0:2
4,4,0:2
5,4,0:106.2
0,5,0:2
1,5,0:2
2,5,0:2
3,5,0:106.4
4,5,0:106.4
2,-12,1:106.1
1,-11,1:106.8
1,-9,1:106.8
2,-8,1:106.4
3,-8,1:106.4
2,-6,1:17.1
1,-5,1:17.1
2,-5,1:17.1
4,-5,1:17.1
8,-5,1:106.8
-6,-4,1:106.8
0,-4,1:17.1
1,-4,1:17.1
2,-4,1:3
3,-4,1:17.1
4,-4,1:17.1
9,-4,1:106.4
0,-3,1:17.1
1,-3,1:3
2,-3,1:3
3,-3,1:3
4,-3,1:2
5,-3,1:17.1
-8,-2,1:106.8
-7,-2,1:106.1
-6,-2,1:106.1
-1,-2,1:2
0,-2,1:3
1,-2,1:2
2,-2,1:2
3,-2,1:2
4,-2,1:2
5,-2,1:3
6,-2,1:17.1
7,-2,1:17.1
-8,-1,1:106.8
-1,-1,1:2
0,-1,1:17.1
1,-1,1:3
2,-1,1:3
3,-1,1:3
4,-1,1:3
5,-1,1:3
6,-1,1:2
-1,0,1:17.1
0,0,1:17.1
1,0,1:17.1
2,0,1:3
3,0,1:3
4,0,1:2
5,0,1:2
6,0,1:2
0,1,1:2
1,1,1:3
2,1,1:3
3,1,1:2
4,1,1:2
5,1,1:2
-1,2,1:2
0,2,1:2
1,2,1:2
2,2,1:17.1
3,2,1:2
4,2,1:2
6,2,1:31.1
-1,3,1:2
0,3,1:2
1,3,1:2
2,3,1:2
3,3,1:2
4,3,1:31.1
5,3,1:31.1
0,4,1:2
1,4,1:2
2,4,1:2
0,5,1:106.4
2,5,1:106.4
4,5,1:106.4
2,-12,2:106.1
1,-11,2:106.8
1,-9,2:106.8
2,-8,2:106.4
3,-8,2:106.4
2,-5,2:17.1
8,-5,2:106.8
-6,-4,2:106.8
1,-4,2:17.1
2,-4,2:17.1
3,-4,2:17.1
4,-4,2:17.1
9,-4,2:106.4
0,-3,2:17.1
1,-3,2:17.1
2,-3,2:17.1
3,-3,2:17.1
-8,-2,2:106.8
-7,-2,2:106.1
-6,-2,2:106.1
0,-2,2:17.1
5,-2,2:17.1
-8,-1,2:106.8
0,-1,2:17.1
1,-1,2:17.1
2,-1,2:17.1
3,-1,2:17.1
4,-1,2:17.1
5,-1,2:17.1
1,0,2:17.1
2,0,2:17.1
3,0,2:17.1
4,0,2:31.1
5,0,2:31.1
1,1,2:17.1
2,1,2:17.1
3,1,2:31.1
4,1,2:31.1
5,1,2:31.1
-1,2,2:31.1
0,5,2:106.4
2,5,2:106.4
4,5,2:106.4
2,-2,2:17.1
1,-2,2:17.1
3,-2,2:17.1
4,-2,2:17.1
4,-3,2:17.1
2,-12,3:106.1
1,-11,3:106.8
1,-9,3:106.8
2,-8,3:106.4
3,-8,3:106.4
8,-5,3:106.8
-6,-4,3:106.8
2,-4,3:17.1
3,-4,3:17.1
9,-4,3:106.4
1,-3,3:17.1
3,-3,3:17.1
-8,-2,3:106.8
-7,-2,3:106.1
-6,-2,3:106.1
0,-2,3:17.1
1,-2,3:17.1
5,-2,3:17.1
-8,-1,3:106.8
0,-1,3:17.1
1,-1,3:17.1
2,-1,3:17.1
3,-1,3:17.1
4,-1,3:17.1
1,0,3:17.1
2,0,3:17.1
0,5,3:106.4
2,5,3:106.4
4,5,3:106.4
2,-2,3:17.1
2,-3,3:17.1
3,-2,3:17.1
4,-2,3:17.1
2,-12,4:106.1
1,-11,4:106.8
1,-9,4:106.8
2,-8,4:106.4
3,-8,4:106.4
8,-5,4:106.8
-6,-4,4:106.8
2,-4,4:17.1
9,-4,4:106.4
1,-3,4:17.1
3,-3,4:17.1
-8,-2,4:106.8
-7,-2,4:106.1
-6,-2,4:106.1
0,-2,4:17.1
1,-2,4:17.1
4,-2,4:17.1
5,-2,4:17.1
-8,-1,4:106.8
1,-1,4:17.1
3,-1,4:17.1
1,0,4:17.1
2,0,4:17.1
0,5,4:106.4
2,5,4:106.4
4,5,4:106.4
2,-2,4:17.1
3,-2,4:17.1
2,-3,4:17.1
2,-1,4:17.1
2,-12,5:106.1
1,-11,5:106.8
1,-9,5:106.8
2,-8,5:106.4
3,-8,5:106.4
8,-5,5:106.8
-6,-4,5:106.8
2,-4,5:17.1
9,-4,5:106.4
1,-3,5:17.1
3,-3,5:17.1
-8,-2,5:106.8
-7,-2,5:106.1
-6,-2,5:106.1
0,-2,5:17.1
1,-2,5:17.1
4,-2,5:17.1
-8,-1,5:106.8
1,-1,5:17.1
3,-1,5:17.1
2,0,5:17.1
0,5,5:106.4
2,5,5:106.4
4,5,5:106.4
2,-2,5:17.1
3,-2,5:17.1
2,-3,5:17.1
2,-1,5:17.1
2,-12,6:106.1
1,-11,6:106.8
1,-9,6:106.8
2,-8,6:106.4
3,-8,6:106.4
8,-5,6:106.8
-6,-4,6:106.8
2,-4,6:17.1
9,-4,6:106.4
0,-3,6:17.1
1,-3,6:17.1
3,-3,6:17.1
-8,-2,6:106.8
-7,-2,6:106.1
-6,-2,6:106.1
0,-2,6:17.1
1,-2,6:17.1
4,-2,6:17.1
-8,-1,6:106.8
1,-1,6:17.1
3,-1,6:17.1
2,0,6:17.1
0,5,6:106.4
2,5,6:106.4
4,5,6:106.4
2,-2,6:17.1
3,-2,6:17.1
2,-3,6:17.1
2,-1,6:17.1
2,-12,7:106.1
1,-11,7:106.8
2,-11,7:18
1,-9,7:106.8
2,-8,7:106.4
3,-8,7:106.4
7,-7,7:18
2,-5,7:17.1
8,-5,7:106.8
9,-5,7:18
-6,-4,7:106.8
1,-4,7:18
2,-4,7:17.1
8,-4,7:106
9,-4,7:106.4
0,-3,7:17.1
1,-3,7:17.1
3,-3,7:17.1
-8,-2,7:106.8
-7,-2,7:106.1
-6,-2,7:106.1
-1,-2,7:17.1
0,-2,7:17.1
1,-2,7:17.1
4,-2,7:17.1
-8,-1,7:106.8
0,-1,7:17.1
1,-1,7:17.1
3,-1,7:17.1
2,0,7:17.1
3,0,7:17.1
0,3,7:18
0,4,7:18
1,4,7:18
4,4,7:18
0,5,7:106.4
2,5,7:106.4
4,5,7:106.4
2,6,7:106
2,7,7:18
2,-3,7:17.1
2,-2,7:17.1
2,-1,7:17.1
3,-2,7:17.1
2,-12,8:18
1,-11,8:18
2,-11,8:17.1
3,-11,8:18
1,-10,8:18
2,-10,8:18
1,-9,8:106.8
2,-9,8:18
3,-9,8:18
2,-8,8:106.4
3,-8,8:106.4
7,-8,8:18
7,-7,8:17.1
8,-7,8:18
7,-6,8:18
9,-6,8:18
1,-5,8:18
2,-5,8:17.1
6,-5,8:18
7,-5,8:18
8,-5,8:18
9,-5,8:17.1
10,-5,8:18
-6,-4,8:106.8
-5,-4,8:18
0,-4,8:17.1
1,-4,8:17.1
2,-4,8:17.1
3,-4,8:17.1
8,-4,8:18
9,-4,8:18
-1,-3,8:18
0,-3,8:17.1
1,-3,8:17.1
2,-3,8:17.1
3,-3,8:17.1
4,-3,8:17.1
-8,-2,8:106.8
-7,-2,8:106.1
-6,-2,8:106.1
-1,-2,8:17.1
0,-2,8:17.1
1,-2,8:17.1
2,-2,8:17.1
3,-2,8:17.1
4,-2,8:17.1
-8,-1,8:106.8
-7,-1,8:18
-6,-1,8:18
0,-1,8:17.1
1,-1,8:17.1
2,-1,8:17.1
3,-1,8:17.1
4,-1,8:17.1
0,0,8:18
1,0,8:17.1
2,0,8:17.1
3,0,8:17.1
1,1,8:18
2,1,8:18
1,2,8:18
-1,3,8:18
0,3,8:18
1,3,8:18
2,3,8:18
4,3,8:18
-1,4,8:18
0,4,8:18
1,4,8:18
2,4,8:18
3,4,8:18
4,4,8:17.1
5,4,8:18
-1,5,8:18
0,5,8:18
1,5,8:18
2,5,8:106.4
4,5,8:18
-1,6,8:18
0,6,8:18
1,6,8:18
2,6,8:18
3,6,8:18
4,6,8:18
1,7,8:18
2,7,8:17.1
3,7,8:18
2,8,8:18
2,-12,9:18
1,-11,9:18
2,-11,9:17.1
3,-11,9:18
1,-10,9:18
2,-10,9:17.1
3,-10,9:17.1
4,-10,9:18
0,-9,9:18
1,-9,9:18
2,-9,9:18
3,-9,9:18
1,-8,9:18
2,-8,9:18
7,-8,9:18
1,-7,9:18
2,-7,9:18
6,-7,9:18
7,-7,9:17.1
8,-7,9:18
-2,-6,9:18
0,-6,9:18
1,-6,9:17.1
2,-6,9:17.1
6,-6,9:18
7,-6,9:17.1
8,-6,9:18
9,-6,9:18
-5,-5,9:18
-3,-5,9:18
-2,-5,9:18
-1,-5,9:18
0,-5,9:18
1,-5,9:17.1
2,-5,9:17.1
3,-5,9:17.1
6,-5,9:17.1
7,-5,9:17.1
8,-5,9:17.1
9,-5,9:17.1
10,-5,9:18
-6,-4,9:18
-5,-4,9:17.1
-4,-4,9:18
-3,-4,9:18
-2,-4,9:18
-1,-4,9:17.1
0,-4,9:17.1
2,-4,9:17.1
3,-4,9:17.1
4,-4,9:17.1
6,-4,9:18
7,-4,9:18
8,-4,9:17.1
9,-4,9:18
-6,-3,9:18
-5,-3,9:18
-3,-3,9:18
-2,-3,9:18
-1,-3,9:17.1
1,-3,9:17.1
3,-3,9:17.1
4,-3,9:17.1
5,-3,9:17.1
8,-3,9:18
-8,-2,9:106.8
-7,-2,9:18
-6,-2,9:18
-5,-2,9:18
-4,-2,9:18
-3,-2,9:18
-2,-2,9:17.1
-1,-2,9:17.1
0,-2,9:17.1
4,-2,9:17.1
5,-2,9:18
-8,-1,9:18
-7,-1,9:17.1
-6,-1,9:17.1
-5,-1,9:18
-2,-1,9:18
-1,-1,9:17.1
0,-1,9:17.1
1,-1,9:17.1
3,-1,9:17.1
4,-1,9:17.1
-7,0,9:18
-6,0,9:18
0,0,9:18
1,0,9:17.1
2,0,9:17.1
3,0,9:17.1
4,0,9:18
5,0,9:18
-1,1,9:18
0,1,9:17.1
1,1,9:17.1
2,1,9:18
3,1,9:17.1
4,1,9:18
-1,2,9:18
0,2,9:18
1,2,9:18
2,2,9:18
3,2,9:18
-1,3,9:18
0,3,9:18
1,3,9:18
2,3,9:18
3,3,9:18
4,3,9:18
-2,4,9:18
-1,4,9:17.1
0,4,9:17.1
1,4,9:17.1
2,4,9:17.1
3,4,9:17.1
4,4,9:17.1
5,4,9:18
-2,5,9:18
-1,5,9:17.1
0,5,9:18
1,5,9:18
2,5,9:17.1
3,5,9:18
4,5,9:18
-2,6,9:18
-1,6,9:17.1
0,6,9:18
1,6,9:18
2,6,9:17.1
3,6,9:18
-1,7,9:18
0,7,9:18
1,7,9:17.1
2,7,9:17.1
3,7,9:18
1,8,9:18
2,8,9:17.1
3,8,9:18
2,9,9:18
1,-4,9:17.1
1,-2,9:17.1
2,-2,9:17.1
2,-3,9:17.1
2,-1,9:17.1
3,-2,9:17.1
0,-3,9:17.1
2,-11,10:18
3,-11,10:18
2,-10,10:18
3,-10,10:17.1
4,-10,10:18
1,-9,10:18
2,-9,10:17.1
3,-9,10:17.1
4,-9,10:18
0,-8,10:18
1,-8,10:17.1
2,-8,10:17.1
-3,-7,10:18
-2,-7,10:18
0,-7,10:18
1,-7,10:17.1
2,-7,10:17.1
3,-7,10:18
7,-7,10:18
-4,-6,10:18
-3,-6,10:18
-2,-6,10:17.1
-1,-6,10:18
0,-6,10:17.1
1,-6,10:17.1
2,-6,10:17.1
3,-6,10:17.1
6,-6,10:18
7,-6,10:18
8,-6,10:18
-5,-5,10:18
-4,-5,10:18
-3,-5,10:17.1
-2,-5,10:17.1
-1,-5,10:17.1
0,-5,10:17.1
1,-5,10:17.1
2,-5,10:17.1
3,-5,10:17.1
4,-5,10:17.1
5,-5,10:17.1
6,-5,10:17.1
7,-5,10:18
8,-5,10:18
9,-5,10:18
-6,-4,10:18
-5,-4,10:17.1
-4,-4,10:18
-3,-4,10:18
-2,-4,10:17.1
-1,-4,10:17.1
0,-4,10:17.1
2,-4,10:17.1
4,-4,10:17.1
5,-4,10:18
6,-4,10:18
7,-4,10:18
8,-4,10:18
-6,-3,10:18
-5,-3,10:17.1
-4,-3,10:18
-3,-3,10:18
-2,-3,10:18
-1,-3,10:17.1
3,-3,10:17.1
4,-3,10:17.1
5,-3,10:17.1
6,-3,10:18
-6,-2,10:18
-5,-2,10:17.1
-4,-2,10:17.1
-3,-2,10:17.1
-2,-2,10:17.1
-1,-2,10:17.1
0,-2,10:17.1
4,-2,10:17.1
5,-2,10:17.1
6,-2,10:18
-7,-1,10:18
-6,-1,10:17.1
-5,-1,10:17.1
-4,-1,10:18
-3,-1,10:18
-2,-1,10:18
-1,-1,10:17.1
0,-1,10:17.1
3,-1,10:17.1
4,-1,10:18
5,-1,10:18
-6,0,10:18
-5,0,10:18
-1,0,10:18
1,0,10:17.1
2,0,10:17.1
3,0,10:17.1
4,0,10:17.1
5,0,10:17.1
6,0,10:18
-2,1,10:18
-1,1,10:18
0,1,10:17.1
1,1,10:17.1
2,1,10:18
3,1,10:17.1
4,1,10:17.1
5,1,10:18
-1,2,10:18
0,2,10:17.1
1,2,10:17.1
2,2,10:18
3,2,10:18
4,2,10:18
5,2,10:18
-2,3,10:18
-1,3,10:17.1
0,3,10:17.1
1,3,10:17.1
2,3,10:18
3,3,10:18
4,3,10:18
-2,4,10:18
-1,4,10:17.1
0,4,10:17.1
1,4,10:18
2,4,10:18
3,4,10:18
4,4,10:18
5,4,10:18
-2,5,10:18
-1,5,10:18
0,5,10:18
1,5,10:18
2,5,10:18
3,5,10:18
-1,6,10:18
0,6,10:18
1,6,10:18
2,6,10:18
3,6,10:18
1,7,10:18
2,7,10:18
3,7,10:18
1,8,10:18
2,8,10:18
3,8,10:18
0,-3,10:17.1
1,-3,10:17.1
1,-4,10:17.1
1,-2,10:17.1
1,-1,10:17.1
2,-1,10:17.1
2,-2,10:17.1
2,-3,10:17.1
3,-2,10:17.1
2,-12,11:18
3,-12,11:18
2,-11,11:18
3,-11,11:18
2,-10,11:18
3,-10,11:17.1
4,-10,11:18
1,-9,11:18
2,-9,11:18
3,-9,11:18
-3,-8,11:18
0,-8,11:18
1,-8,11:18
2,-8,11:18
-4,-7,11:18
-3,-7,11:17.1
-2,-7,11:18
-1,-7,11:18
0,-7,11:17.1
1,-7,11:17.1
2,-7,11:18
4,-7,11:18
-5,-6,11:18
-4,-6,11:17.1
-3,-6,11:17.1
-2,-6,11:17.1
-1,-6,11:18
0,-6,11:18
1,-6,11:17.1
2,-6,11:18
3,-6,11:18
4,-6,11:17.1
5,-6,11:18
-4,-5,11:18
-3,-5,11:17.1
-2,-5,11:17.1
-1,-5,11:17.1
0,-5,11:18
1,-5,11:17.1
2,-5,11:17.1
3,-5,11:17.1
4,-5,11:17.1
6,-5,11:18
7,-5,11:18
-5,-4,11:18
-3,-4,11:18
-2,-4,11:18
-1,-4,11:17.1
0,-4,11:17.1
2,-4,11:17.1
3,-4,11:18
4,-4,11:17.1
5,-4,11:18
6,-4,11:18
-5,-3,11:18
-4,-3,11:18
-3,-3,11:18
-2,-3,11:18
-1,-3,11:17.1
3,-3,11:17.1
4,-3,11:17.1
5,-3,11:17.1
6,-3,11:17.1
7,-3,11:18
-5,-2,11:18
-4,-2,11:18
-3,-2,11:17.1
-2,-2,11:17.1
-1,-2,11:17.1
0,-2,11:17.1
3,-2,11:17.1
4,-2,11:17.1
5,-2,11:17.1
6,-2,11:18
-6,-1,11:18
-5,-1,11:18
-4,-1,11:18
-3,-1,11:18
-2,-1,11:17.1
-1,-1,11:17.1
0,-1,11:17.1
3,-1,11:17.1
4,-1,11:17.1
5,-1,11:18
6,-1,11:18
-2,0,11:18
-1,0,11:18
0,0,11:17.1
1,0,11:17.1
2,0,11:17.1
4,0,11:17.1
5,0,11:17.1
6,0,11:18
7,0,11:18
-2,1,11:18
-1,1,11:17.1
0,1,11:17.1
1,1,11:17.1
2,1,11:17.1
3,1,11:18
4,1,11:17.1
5,1,11:17.1
6,1,11:18
-2,2,11:18
-1,2,11:18
0,2,11:17.1
1,2,11:17.1
2,2,11:18
3,2,11:18
4,2,11:18
5,2,11:17.1
6,2,11:18
-2,3,11:18
-1,3,11:18
0,3,11:18
1,3,11:18
2,3,11:18
3,3,11:18
4,3,11:18
5,3,11:18
-2,4,11:18
-1,4,11:18
0,4,11:18
1,4,11:18
2,4,11:18
3,4,11:18
-1,5,11:18
0,5,11:18
1,5,11:18
2,5,11:18
0,6,11:18
1,6,11:18
2,6,11:18
3,6,11:18
1,7,11:18
2,7,11:18
3,7,11:18
0,-3,11:17.1
1,-2,11:17.1
1,-3,11:17.1
1,-4,11:17.1
1,-1,11:17.1
2,-1,11:17.1
2,-2,11:17.1
2,-3,11:17.1
2,-12,12:18
3,-12,12:18
2,-11,12:18
3,-11,12:17.1
4,-11,12:18
0,-10,12:18
1,-10,12:18
2,-10,12:18
3,-10,12:17.1
4,-10,12:18
-3,-9,12:18
-1,-9,12:18
0,-9,12:18
1,-9,12:18
2,-9,12:18
3,-9,12:18
4,-9,12:18
-4,-8,12:18
-3,-8,12:17.1
-2,-8,12:18
-1,-8,12:18
0,-8,12:17.1
1,-8,12:18
2,-8,12:18
-5,-7,12:18
-4,-7,12:17.1
-3,-7,12:17.1
-2,-7,12:18
-1,-7,12:18
0,-7,12:17.1
1,-7,12:17.1
2,-7,12:18
4,-7,12:18
5,-7,12:18
-5,-6,12:18
-4,-6,12:17.1
-3,-6,12:17.1
3,-6,12:18
4,-6,12:17.1
5,-6,12:17.1
6,-6,12:18
-4,-5,12:18
1,-5,12:17.1
2,-5,12:17.1
4,-5,12:17.1
5,-5,12:17.1
6,-5,12:18
10,-5,12:18
11,-5,12:18
-4,-4,12:18
-3,-4,12:18
-2,-4,12:18
-1,-4,12:17.1
0,-4,12:17.1
2,-4,12:17.1
5,-4,12:17.1
6,-4,12:17.1
7,-4,12:18
8,-4,12:18
9,-4,12:18
-6,-3,12:18
-5,-3,12:18
-4,-3,12:18
-3,-3,12:18
-2,-3,12:18
-1,-3,12:17.1
0,-3,12:17.1
1,-3,12:17.1
2,-3,12:17.1
3,-3,12:17.1
5,-3,12:17.1
6,-3,12:17.1
7,-3,12:17.1
8,-3,12:18
9,-3,12:18
-6,-2,12:18
-5,-2,12:18
-4,-2,12:18
-3,-2,12:17.1
-2,-2,12:18
-1,-2,12:17.1
0,-2,12:17.1
3,-2,12:17.1
4,-2,12:17.1
5,-2,12:17.1
6,-2,12:18
7,-2,12:18
-5,-1,12:18
-4,-1,12:18
-3,-1,12:17.1
-2,-1,12:17.1
-1,-1,12:17.1
0,-1,12:17.1
3,-1,12:17.1
5,-1,12:17.1
6,-1,12:17.1
7,-1,12:18
-5,0,12:18
-4,0,12:18
-3,0,12:18
-2,0,12:18
1,0,12:17.1
2,0,12:17.1
5,0,12:17.1
6,0,12:17.1
7,0,12:18
-2,1,12:18
4,1,12:17.1
5,1,12:17.1
-2,2,12:18
-1,2,12:18
0,2,12:17.1
1,2,12:17.1
3,2,12:18
4,2,12:18
5,2,12:17.1
6,2,12:18
7,2,12:18
-2,3,12:18
-1,3,12:17.1
0,3,12:17.1
1,3,12:17.1
2,3,12:17.1
3,3,12:18
4,3,12:18
5,3,12:18
6,3,12:18
-2,4,12:18
-1,4,12:18
0,4,12:18
1,4,12:18
2,4,12:17.1
3,4,12:17.1
4,4,12:18
5,4,12:18
-3,5,12:18
-2,5,12:18
-1,5,12:18
0,5,12:18
1,5,12:18
2,5,12:18
3,5,12:18
-3,6,12:18
2,6,12:18
3,6,12:18
1,-2,12:17.1
1,-4,12:17.1
1,-1,12:17.1
2,-1,12:17.1
2,-2,12:17.1
0,-11,13:18
2,-11,13:18
3,-11,13:18
-3,-10,13:18
-1,-10,13:18
0,-10,13:17.1
1,-10,13:18
2,-10,13:18
3,-10,13:18
-4,-9,13:18
-3,-9,13:18
-2,-9,13:18
-1,-9,13:17.1
0,-9,13:17.1
1,-9,13:17.1
2,-9,13:18
-5,-8,13:18
-4,-8,13:17.1
-1,-8,13:18
0,-8,13:17.1
1,-8,13:17.1
2,-8,13:18
5,-8,13:18
-6,-7,13:18
-5,-7,13:17.1
-4,-7,13:17.1
-3,-7,13:17.1
2,-7,13:18
3,-7,13:18
4,-7,13:18
5,-7,13:18
6,-7,13:18
-6,-6,13:18
-5,-6,13:17.1
-4,-6,13:17.1
3,-6,13:18
4,-6,13:17.1
5,-6,13:18
6,-6,13:18
7,-6,13:18
10,-6,13:18
11,-6,13:18
-6,-5,13:18
-5,-5,13:18
1,-5,13:17.1
2,-5,13:17.1
5,-5,13:17.1
6,-5,13:17.1
7,-5,13:18
8,-5,13:18
9,-5,13:18
10,-5,13:18
11,-5,13:18
12,-5,13:18
-6,-4,13:18
-5,-4,13:18
-4,-4,13:18
-2,-4,13:17.1
-1,-4,13:17.1
0,-4,13:17.1
1,-4,13:17.1
8,-4,13:17.1
9,-4,13:17.1
10,-4,13:18
11,-4,13:18
-7,-3,13:18
-6,-3,13:18
-5,-3,13:18
-4,-3,13:18
-2,-3,13:17.1
-1,-3,13:17.1
1,-3,13:17.1
2,-3,13:17.1
3,-3,13:17.1
6,-3,13:17.1
7,-3,13:17.1
8,-3,13:17.1
9,-3,13:17.1
10,-3,13:18
-9,-2,13:18
-7,-2,13:18
-6,-2,13:18
-5,-2,13:18
-4,-2,13:17.1
-1,-2,13:17.1
0,-2,13:17.1
1,-2,13:17.1
2,-2,13:17.1
3,-2,13:17.1
4,-2,13:17.1
6,-2,13:18
7,-2,13:18
8,-2,13:18
9,-2,13:18
-6,-1,13:18
-5,-1,13:18
-4,-1,13:17.1
-3,-1,13:17.1
-2,-1,13:17.1
0,-1,13:17.1
1,-1,13:17.1
2,-1,13:17.1
3,-1,13:17.1
6,-1,13:17.1
7,-1,13:18
-6,0,13:18
-5,0,13:18
-4,0,13:18
-3,0,13:18
-2,0,13:17.1
1,0,13:17.1
2,0,13:17.1
5,0,13:17.1
6,0,13:18
7,0,13:18
8,0,13:18
-5,1,13:18
-4,1,13:18
-2,1,13:18
-2,2,13:18
-1,2,13:18
4,2,13:18
5,2,13:17.1
6,2,13:17.1
7,2,13:18
-3,3,13:18
-2,3,13:18
-1,3,13:17.1
1,3,13:17.1
3,3,13:18
4,3,13:18
5,3,13:18
6,3,13:18
7,3,13:18
-3,4,13:18
-2,4,13:17.1
-1,4,13:17.1
0,4,13:18
1,4,13:18
2,4,13:18
3,4,13:17.1
4,4,13:18
5,4,13:18
6,4,13:18
-4,5,13:18
-3,5,13:17.1
-2,5,13:17.1
-1,5,13:18
1,5,13:18
2,5,13:18
3,5,13:17.1
4,5,13:18
5,5,13:18
-3,6,13:18
-2,6,13:18
2,6,13:18
3,6,13:18
0,-3,13:17.1
0,-11,14:18
1,-11,14:18
2,-11,14:18
3,-11,14:18
-5,-10,14:18
-4,-10,14:18
-1,-10,14:18
0,-10,14:17.1
1,-10,14:17.1
2,-10,14:17.1
3,-10,14:18
-5,-9,14:18
-4,-9,14:17.1
-3,-9,14:18
-1,-9,14:18
0,-9,14:18
1,-9,14:17.1
2,-9,14:17.1
3,-9,14:18
5,-9,14:18
-5,-8,14:18
-4,-8,14:17.1
0,-8,14:18
1,-8,14:18
2,-8,14:18
3,-8,14:18
4,-8,14:18
5,-8,14:17.1
6,-8,14:18
-6,-7,14:18
-5,-7,14:18
3,-7,14:18
4,-7,14:17.1
5,-7,14:17.1
6,-7,14:18
11,-7,14:18
-7,-6,14:18
-6,-6,14:17.1
-5,-6,14:17.1
-4,-6,14:17.1
2,-6,14:18
3,-6,14:18
4,-6,14:17.1
5,-6,14:18
6,-6,14:18
7,-6,14:18
9,-6,14:18
10,-6,14:18
11,-6,14:17.1
12,-6,14:18
-7,-5,14:18
-6,-5,14:17.1
-5,-5,14:17.1
2,-5,14:17.1
6,-5,14:17.1
7,-5,14:18
8,-5,14:18
9,-5,14:18
10,-5,14:17.1
11,-5,14:17.1
12,-5,14:17.1
13,-5,14:18
-6,-4,14:18
-5,-4,14:18
-4,-4,14:18
-2,-4,14:17.1
-1,-4,14:17.1
8,-4,14:18
9,-4,14:17.1
10,-4,14:17.1
11,-4,14:18
12,-4,14:18
-9,-3,14:18
-7,-3,14:18
-6,-3,14:18
-5,-3,14:18
-4,-3,14:17.1
-2,-3,14:17.1
1,-3,14:17.1
2,-3,14:17.1
3,-3,14:17.1
6,-3,14:17.1
7,-3,14:17.1
8,-3,14:18
9,-3,14:18
10,-3,14:18
11,-3,14:18
-10,-2,14:18
-9,-2,14:18
-8,-2,14:18
-7,-2,14:18
-6,-2,14:18
-5,-2,14:18
-4,-2,14:17.1
1,-2,14:17.1
2,-2,14:17.1
3,-2,14:17.1
4,-2,14:17.1
6,-2,14:18
7,-2,14:18
-10,-1,14:18
-9,-1,14:18
-8,-1,14:18
-5,-1,14:18
-4,-1,14:18
-3,-1,14:18
-2,-1,14:17.1
0,-1,14:17.1
1,-1,14:17.1
2,-1,14:17.1
3,-1,14:17.1
6,-1,14:17.1
7,-1,14:17.1
8,-1,14:18
9,-1,14:18
10,-1,14:18
-6,0,14:18
-5,0,14:18
-4,0,14:18
-3,0,14:18
-2,0,14:17.1
1,0,14:17.1
2,0,14:17.1
5,0,14:17.1
6,0,14:18
7,0,14:17.1
8,0,14:17.1
9,0,14:18
-4,1,14:18
-3,1,14:18
-2,1,14:17.1
2,1,14:17.1
3,1,14:17.1
7,1,14:18
8,1,14:18
-4,2,14:18
-3,2,14:18
-2,2,14:18
4,2,14:18
5,2,14:17.1
6,2,14:18
-3,3,14:18
-2,3,14:18
-1,3,14:18
1,3,14:17.1
4,3,14:18
5,3,14:17.1
6,3,14:18
7,3,14:18
-3,4,14:18
-2,4,14:18
-1,4,14:18
1,4,14:17.1
2,4,14:18
3,4,14:18
4,4,14:18
5,4,14:17.1
6,4,14:17.1
7,4,14:18
-3,5,14:18
-2,5,14:18
0,5,14:18
1,5,14:17.1
2,5,14:18
3,5,14:17.1
4,5,14:18
5,5,14:18
6,5,14:18
1,6,14:18
2,6,14:18
3,6,14:18
2,-12,15:18
-5,-11,15:18
-4,-11,15:18
1,-11,15:18
2,-11,15:17.1
3,-11,15:18
-6,-10,15:18
-5,-10,15:17.1
-4,-10,15:17.1
-3,-10,15:18
0,-10,15:18
1,-10,15:18
2,-10,15:17.1
3,-10,15:18
5,-10,15:18
-5,-9,15:18
-4,-9,15:17.1
-3,-9,15:17.1
-2,-9,15:18
1,-9,15:18
2,-9,15:18
5,-9,15:18
6,-9,15:18
-4,-8,15:18
-3,-8,15:17.1
-2,-8,15:18
4,-8,15:18
5,-8,15:17.1
6,-8,15:18
2,-7,15:18
4,-7,15:18
5,-7,15:18
-6,-6,15:18
-5,-6,15:18
-4,-6,15:18
2,-6,15:18
4,-6,15:18
11,-6,15:18
-7,-5,15:18
-6,-5,15:17.1
-5,-5,15:18
-2,-5,15:17.1
2,-5,15:17.1
6,-5,15:18
9,-5,15:18
10,-5,15:18
11,-5,15:17.1
12,-5,15:18
-9,-4,15:18
-7,-4,15:18
-6,-4,15:18
-5,-4,15:18
-4,-4,15:18
-2,-4,15:17.1
9,-4,15:18
10,-4,15:17.1
11,-4,15:18
12,-4,15:18
-10,-3,15:18
-9,-3,15:17.1
-8,-3,15:18
-7,-3,15:17.1
-6,-3,15:17.1
-5,-3,15:17.1
-4,-3,15:17.1
1,-3,15:17.1
2,-3,15:17.1
3,-3,15:18
6,-3,15:18
7,-3,15:17.1
10,-3,15:18
-11,-2,15:18
-10,-2,15:17.1
-9,-2,15:17.1
-8,-2,15:17.1
-7,-2,15:17.1
-6,-2,15:18
-5,-2,15:18
-4,-2,15:17.1
1,-2,15:17.1
2,-2,15:17.1
3,-2,15:17.1
4,-2,15:17.1
6,-2,15:18
7,-2,15:18
8,-2,15:18
9,-2,15:18
10,-2,15:18
-10,-1,15:18
-9,-1,15:17.1
-8,-1,15:18
-7,-1,15:18
-6,-1,15:18
-5,-1,15:18
-4,-1,15:18
-3,-1,15:17.1
1,-1,15:17.1
6,-1,15:18
7,-1,15:18
8,-1,15:17.1
9,-1,15:17.1
10,-1,15:17.1
11,-1,15:18
-9,0,15:18
-8,0,15:18
-4,0,15:18
-3,0,15:18
-2,0,15:18
1,0,15:17.1
5,0,15:17.1
6,0,15:18
7,0,15:18
8,0,15:17.1
9,0,15:18
10,0,15:18
-4,1,15:18
-3,1,15:18
-2,1,15:17.1
3,1,15:17.1
8,1,15:18
-3,2,15:18
-2,2,15:18
3,2,15:17.1
5,2,15:18
6,2,15:18
-3,3,15:18
-2,3,15:18
-1,3,15:18
1,3,15:17.1
5,3,15:18
6,3,15:18
-2,4,15:18
1,4,15:18
5,4,15:18
6,4,15:17.1
7,4,15:18
0,5,15:18
1,5,15:17.1
2,5,15:18
3,5,15:18
6,5,15:18
7,5,15:18
0,6,15:18
1,6,15:17.1
2,6,15:18
1,7,15:18
2,-1,15:17.1
3,-1,15:17.1
-4,-11,16:18
2,-11,16:18
-5,-10,16:18
-4,-10,16:17.1
-3,-10,16:18
1,-10,16:18
2,-10,16:18
5,-10,16:18
-4,-9,16:18
-3,-9,16:18
4,-9,16:18
5,-9,16:17.1
6,-9,16:18
-3,-8,16:18
2,-8,16:18
4,-8,16:18
5,-8,16:17.1
6,-8,16:18
1,-7,16:18
2,-7,16:17.1
3,-7,16:18
4,-7,16:18
5,-7,16:18
-3,-6,16:18
-2,-6,16:18
1,-6,16:18
2,-6,16:17.1
3,-6,16:18
4,-6,16:18
10,-6,16:18
11,-6,16:18
-6,-5,16:18
-5,-5,16:18
-3,-5,16:17.1
-2,-5,16:17.1
2,-5,16:17.1
3,-5,16:18
7,-5,16:18
10,-5,16:18
11,-5,16:17.1
12,-5,16:18
-8,-4,16:18
-6,-4,16:18
-5,-4,16:18
6,-4,16:18
7,-4,16:17.1
8,-4,16:18
10,-4,16:18
11,-4,16:18
-9,-3,16:18
-8,-3,16:18
-7,-3,16:18
-6,-3,16:18
-5,-3,16:18
1,-3,16:17.1
2,-3,16:17.1
3,-3,16:18
4,-3,16:18
5,-3,16:18
6,-3,16:18
7,-3,16:17.1
8,-3,16:18
-10,-2,16:18
-9,-2,16:18
-8,-2,16:18
-7,-2,16:17.1
-6,-2,16:18
-5,-2,16:18
-4,-2,16:17.1
-3,-2,16:18
1,-2,16:17.1
2,-2,16:17.1
3,-2,16:17.1
4,-2,16:17.1
5,-2,16:17.1
7,-2,16:18
10,-2,16:18
-9,-1,16:18
-8,-1,16:18
-7,-1,16:18
-6,-1,16:18
-5,-1,16:18
2,-1,16:17.1
6,-1,16:18
7,-1,16:18
8,-1,16:18
9,-1,16:18
10,-1,16:17.1
11,-1,16:18
-8,0,16:18
-5,0,16:18
-4,0,16:18
-3,0,16:18
0,0,16:17.1
1,0,16:17.1
5,0,16:17.1
6,0,16:18
8,0,16:18
10,0,16:18
-5,1,16:18
-4,1,16:17.1
-3,1,16:17.1
-2,1,16:17.1
0,1,16:17.1
3,1,16:18
-4,2,16:18
-3,2,16:18
-2,2,16:17.1
2,2,16:18
3,2,16:17.1
-3,3,16:18
-2,3,16:17.1
-1,3,16:18
1,3,16:17.1
-2,4,16:18
6,4,16:18
0,5,16:18
1,5,16:18
0,6,16:18
1,6,16:17.1
2,6,16:18
1,7,16:18
1,-1,16:17.1
3,-1,16:17.1
-5,-10,17:18
-4,-10,17:18
-4,-9,17:18
5,-9,17:18
5,-8,17:18
2,-7,17:18
-4,-6,17:18
-3,-6,17:18
1,-6,17:18
2,-6,17:18
3,-6,17:18
-4,-5,17:18
-3,-5,17:17.1
-2,-5,17:18
1,-5,17:18
2,-5,17:18
11,-5,17:18
-8,-4,17:18
-6,-4,17:18
-5,-4,17:18
-4,-4,17:18
-3,-4,17:18
1,-4,17:17.1
3,-4,17:18
7,-4,17:18
-9,-3,17:18
-8,-3,17:18
-7,-3,17:18
-5,-3,17:18
-4,-3,17:18
1,-3,17:17.1
2,-3,17:17.1
3,-3,17:17.1
7,-3,17:18
-10,-2,17:18
-9,-2,17:18
-8,-2,17:18
-7,-2,17:18
-6,-2,17:18
-5,-2,17:18
-4,-2,17:17.1
-3,-2,17:18
1,-2,17:17.1
2,-2,17:17.1
6,-2,17:18
-9,-1,17:18
-8,-1,17:18
-7,-1,17:18
-6,-1,17:18
-5,-1,17:18
-4,-1,17:18
2,-1,17:17.1
5,-1,17:18
6,-1,17:17.1
7,-1,17:18
10,-1,17:18
-4,0,17:18
1,0,17:17.1
5,0,17:17.1
6,0,17:17.1
7,0,17:18
-5,1,17:18
-4,1,17:17.1
-3,1,17:18
-2,1,17:18
-1,1,17:18
0,1,17:17.1
3,1,17:18
4,1,17:18
5,1,17:18
6,1,17:18
-4,2,17:18
-3,2,17:18
-2,2,17:18
2,2,17:18
3,2,17:17.1
4,2,17:17.1
5,2,17:18
-3,3,17:18
-2,3,17:17.1
-1,3,17:18
0,3,17:18
1,3,17:17.1
3,3,17:18
4,3,17:17.1
5,3,17:18
-2,4,17:18
1,4,17:18
4,4,17:18
1,5,17:18
1,6,17:18
1,-1,17:17.1
3,-1,17:17.1
3,-2,17:17.1
-4,-10,18:18
-4,-7,18:18
-5,-6,18:18
-4,-6,18:17.1
-3,-6,18:18
1,-6,18:18
2,-6,18:18
-5,-5,18:18
-4,-5,18:17.1
-3,-5,18:17.1
-2,-5,18:18
0,-5,18:18
1,-5,18:18
2,-5,18:18
-5,-4,18:18
-4,-4,18:18
-3,-4,18:18
0,-4,18:18
1,-4,18:17.1
2,-4,18:18
3,-4,18:18
4,-4,18:18
-8,-3,18:18
-7,-3,18:18
-6,-3,18:18
-5,-3,18:18
-4,-3,18:18
-3,-3,18:18
1,-3,18:18
3,-3,18:17.1
4,-3,18:18
-9,-2,18:18
-7,-2,18:18
-6,-2,18:18
-5,-2,18:18
-4,-2,18:17.1
-3,-2,18:18
-2,-2,18:18
-1,-2,18:18
0,-2,18:17.1
1,-2,18:17.1
-4,-1,18:18
5,-1,18:18
6,-1,18:18
1,0,18:17.1
5,0,18:18
6,0,18:17.1
7,0,18:18
-4,1,18:18
-1,1,18:18
0,1,18:17.1
5,1,18:18
6,1,18:18
-3,2,18:18
0,2,18:18
3,2,18:18
4,2,18:18
-2,3,18:18
0,3,18:18
1,3,18:17.1
2,3,18:18
3,3,18:18
4,3,18:17.1
5,3,18:18
0,4,18:18
1,4,18:17.1
2,4,18:17.1
3,4,18:18
4,4,18:18
1,5,18:18
2,5,18:18
1,-8,19:18
0,-7,19:18
1,-7,19:18
2,-7,19:18
-4,-6,19:18
-3,-6,19:18
-1,-6,19:18
0,-6,19:18
1,-6,19:18
2,-6,19:18
-5,-5,19:18
-4,-5,19:18
-3,-5,19:18
-1,-5,19:18
0,-5,19:18
1,-5,19:17.1
2,-5,19:18
4,-5,19:18
-5,-4,19:18
-4,-4,19:18
-3,-4,19:18
-1,-4,19:18
0,-4,19:18
1,-4,19:17.1
2,-4,19:18
3,-4,19:18
4,-4,19:17.1
5,-4,19:18
-5,-3,19:18
-4,-3,19:18
3,-3,19:17.1
4,-3,19:17.1
5,-3,19:18
-5,-2,19:18
-4,-2,19:18
-3,-2,19:18
-1,-2,19:18
0,-2,19:17.1
1,-2,19:18
4,-2,19:18
-4,-1,19:18
-1,-1,19:18
0,-1,19:17.1
1,-1,19:18
6,-1,19:18
7,-1,19:18
8,-1,19:18
0,0,19:18
1,0,19:17.1
5,0,19:18
6,0,19:17.1
7,0,19:17.1
8,0,19:18
-1,1,19:18
0,1,19:17.1
1,1,19:18
5,1,19:18
6,1,19:17.1
7,1,19:18
8,1,19:18
-1,2,19:18
0,2,19:17.1
4,2,19:18
5,2,19:18
6,2,19:18
7,2,19:18
0,3,19:18
1,3,19:18
2,3,19:18
3,3,19:18
4,3,19:17.1
5,3,19:17.1
6,3,19:18
1,4,19:18
2,4,19:17.1
3,4,19:18
4,4,19:18
5,4,19:18
6,4,19:18
1,5,19:18
2,5,19:18
2,6,19:18
1,-9,20:18
0,-8,20:18
1,-8,20:17.1
2,-8,20:18
-1,-7,20:18
0,-7,20:18
1,-7,20:17.1
2,-7,20:18
-4,-6,20:18
-1,-6,20:18
0,-6,20:18
1,-6,20:17.1
2,-6,20:18
-4,-5,20:18
-1,-5,20:18
0,-5,20:17.1
1,-5,20:17.1
2,-5,20:18
4,-5,20:18
0,-4,20:18
1,-4,20:18
2,-4,20:18
3,-4,20:18
4,-4,20:17.1
5,-4,20:18
-4,-3,20:18
-2,-3,20:18
-1,-3,20:18
0,-3,20:18
3,-3,20:18
4,-3,20:18
-4,-2,20:18
-3,-2,20:18
-2,-2,20:18
-1,-2,20:18
0,-2,20:18
-2,-1,20:18
-1,-1,20:18
0,-1,20:17.1
1,-1,20:18
0,0,20:18
1,0,20:17.1
2,0,20:18
6,0,20:18
7,0,20:18
0,1,20:18
2,1,20:18
3,1,20:18
5,1,20:18
6,1,20:18
7,1,20:18
-1,2,20:18
0,2,20:17.1
1,2,20:18
5,2,20:18
0,3,20:18
1,3,20:18
2,3,20:18
3,3,20:18
4,3,20:18
5,3,20:18
1,4,20:18
2,4,20:17.1
3,4,20:18
1,5,20:18
2,5,20:17.1
3,5,20:18
2,6,20:18
1,-8,21:18
0,-7,21:18
1,-7,21:18
1,-6,21:18
2,-6,21:18
4,-6,21:18
0,-5,21:18
1,-5,21:18
2,-5,21:18
3,-5,21:18
4,-5,21:17.1
5,-5,21:18
3,-4,21:18
4,-4,21:17.1
5,-4,21:17.1
6,-4,21:18
-1,-3,21:18
4,-3,21:18
5,-3,21:18
-2,-2,21:18
-1,-2,21:18
0,-1,21:18
1,-1,21:18
2,-1,21:18
0,0,21:18
1,0,21:17.1
2,0,21:17.1
3,0,21:18
1,1,21:18
2,1,21:17.1
3,1,21:17.1
4,1,21:18
0,2,21:18
2,2,21:18
3,2,21:18
2,4,21:18
2,5,21:18
4,-5,22:18
4,-4,22:18
5,-4,22:18
-1,-2,22:18
1,-1,22:18
2,-1,22:18
1,0,22:18
2,0,22:17.1
3,0,22:18
1,1,22:18
2,1,22:18
3,1,22:18
2,0,23:18
0,0,-1:3
0,-1,-1:3
0,-2,-1:3
0,-3,-1:3
0,-4,-1:3
0,-5,-1:3
-1,0,-1:3
-1,-1,-1:3
-1,-2,-1:3
-1,-3,-1:3
-1,-4,-1:3
-2,-2,-1:3
-3,-1,-1:2
-3,-2,-1:2
-3,-3,-1:2
-3,-4,-1:2
-2,-4,-1:2
-2,-5,-1:2
-2,-3,-1:3
-2,-1,-1:3
-2,0,-1:3
-2,1,-1:3
-2,2,-1:3
-3,2,-1:2
-1,2,-1:3
-1,3,-1:3
-2,3,-1:3
-3,1,-1:2
-3,0,-1:2
0,3,-1:3
1,3,-1:3
1,2,-1:3
2,2,-1:3
2,1,-1:3
2,0,-1:3
3,0,-1:3
3,-1,-1:3
2,-1,-1:3
1,0,-1:3
0,1,-1:3
-1,1,-1:3
0,2,-1:3
1,1,-1:3
1,-1,-1:3
2,-2,-1:3
1,-2,-1:3
1,-3,-1:3
1,-4,-1:3
2,-3,-1:3
3,-2,-1:3
3,1,-1:3
3,2,-1:3
2,3,-1:3
1,4,-1:3
0,4,-1:3
3,3,-1:3
3,4,-1:3
2,4,-1:3
4,0,-1:3
4,1,-1:3
4,2,-1:3
4,3,-1:3
-1,4,-1:3
-2,4,-1:2
-3,3,-1:2
5,1,-1:3
3,-3,-1:3
4,-3,-1:3
4,-2,-1:3
4,-1,-1:3
2,-4,-1:3
3,-4,-1:3
4,-4,-1:3
2,-5,-1:3
3,-5,-1:3
6,-5,-1:3
6,-4,-1:3
6,-3,-1:3
6,-2,-1:3
6,-1,-1:3
6,0,-1:3
5,0,-1:3
5,-1,-1:3
5,-2,-1:3
5,-3,-1:3
5,-4,-1:3
5,-5,-1:3
4,-5,-1:3
1,-5,-1:3
-1,-5,-1:3
0,-6,-1:3
1,-6,-1:3
2,-6,-1:3
3,-6,-1:3
4,-6,-1:3
5,-6,-1:3
5,2,-1:3
6,1,-1:3
